Workbook

Sheet clean
A1: id | B1: nombre_completo | C1: id | D1: apellido_nombre | E1: edad | F1: sexo | G1: distrito | H1: pactos | I1: cambio_pacto | J1: pueblo_originario | K1: lista_convencion | L1: partido | M1: inp_ip_mp
A2: 1 | B2: ADOLFO NONATO MILLABUR ÑANCUIL | C2: 1 | D2: Millabur, Adolfo | E2: =VLOOKUP(C2,Tabla1[[id]:[EDAD]],4,FALSE) -> 55 | F2: =IF(Tabla1[[#This Row],[SEXO]]="Masculino",0,1) -> 0 | G2: =VLOOKUP(C2,Tabla1[[id]:[DISTRITO ]],6,FALSE) -> 29 | H2: =VLOOKUP(Tabla1[[#This Row],[PACTO POR EL QUE FUE ELECTO]],ref!$A$2:$B$8,2,FALSE) -> 6 | I2: =IF(Tabla1[[#This Row],[CAMBIO DE PACTO DURANTE CONVENCIÓN]]="",0,1) -> 0 | J2: =IF(Tabla1[[#This Row],[PUEBLO ORIGINARIO]]="",0,1) -> 1 | K2: =VLOOKUP(Tabla1[[#This Row],[LISTA EN LA CONVENCIÓN]],ref!A$11:B$21,2,FALSE) -> 10 | L2: {=IFERROR(VLOOKUP(Tabla1[PARTIDO POLÍTICO],partidos_indep!$A$2:$I$27,9,FALSE),VLOOKUP(Tabla1[[#This Row],[PUEBLO ORIGINARIO]],ref!$A$24:$B$33,2,FALSE))} -> 17 | M2: =VLOOKUP(C2,inp_ip_mp!$B$2:$C$156,2,FALSE) -> 1
A3: 2 | B3: ADRIANA CAMILA AMPUERO BARRIENTOS | C3: 2 | D3: Ampuero, Adriana | E3: =VLOOKUP(C3,Tabla1[[id]:[EDAD]],4,FALSE) -> 35 | F3: =IF(Tabla1[[#This Row],[SEXO]]="Masculino",0,1) -> 1 | G3: =VLOOKUP(C3,Tabla1[[id]:[DISTRITO ]],6,FALSE) -> 26 | H3: =VLOOKUP(Tabla1[[#This Row],[PACTO POR EL QUE FUE ELECTO]],ref!$A$2:$B$8,2,FALSE) -> 3 | I3: =IF(Tabla1[[#This Row],[CAMBIO DE PACTO DURANTE CONVENCIÓN]]="",0,1) -> 1 | J3: =IF(Tabla1[[#This Row],[PUEBLO ORIGINARIO]]="",0,1) -> 0 | K3: =VLOOKUP(Tabla1[[#This Row],[LISTA EN LA CONVENCIÓN]],ref!A$11:B$21,2,FALSE) -> 8 | L3: 0 | M3: =VLOOKUP(C3,inp_ip_mp!$B$2:$C$156,2,FALSE) -> 0
A4: 3 | B4: ADRIANA JANET MERCEDES CANCINO MENESES | C4: 3 | D4: Cancino, Adriana | E4: =VLOOKUP(C4,Tabla1[[id]:[EDAD]],4,FALSE) -> 59 | F4: =IF(Tabla1[[#This Row],[SEXO]]="Masculino",0,1) -> 1 | G4: =VLOOKUP(C4,Tabla1[[id]:[DISTRITO ]],6,FALSE) -> 16 | H4: =VLOOKUP(Tabla1[[#This Row],[PACTO POR EL QUE FUE ELECTO]],ref!$A$2:$B$8,2,FALSE) -> 1 | I4: =IF(Tabla1[[#This Row],[CAMBIO DE PACTO DURANTE CONVENCIÓN]]="",0,1) -> 0 | J4: =IF(Tabla1[[#This Row],[PUEBLO ORIGINARIO]]="",0,1) -> 0 | K4: =VLOOKUP(Tabla1[[#This Row],[LISTA EN LA CONVENCIÓN]],ref!A$11:B$21,2,FALSE) -> 3 | L4: 0 | M4: =VLOOKUP(C4,inp_ip_mp!$B$2:$C$156,2,FALSE) -> 1
A5: 4 | B5: AGUSTÍN SQUELLA NARDUCCI | C5: 4 | D5: Squella, Agustín | E5: =VLOOKUP(C5,Tabla1[[id]:[EDAD]],4,FALSE) -> 78 | F5: =IF(Tabla1[[#This Row],[SEXO]]="Masculino",0,1) -> 0 | G5: =VLOOKUP(C5,Tabla1[[id]:[DISTRITO ]],6,FALSE) -> 7 | H5: =VLOOKUP(Tabla1[[#This Row],[PACTO POR EL QUE FUE ELECTO]],ref!$A$2:$B$8,2,FALSE) -> 1 | I5: =IF(Tabla1[[#This Row],[CAMBIO DE PACTO DURANTE CONVENCIÓN]]="",0,1) -> 0 | J5: =IF(Tabla1[[#This Row],[PUEBLO ORIGINARIO]]="",0,1) -> 0 | K5: =VLOOKUP(Tabla1[[#This Row],[LISTA EN LA CONVENCIÓN]],ref!A$11:B$21,2,FALSE) -> 2 | L5: 0 | M5: =VLOOKUP(C5,inp_ip_mp!$B$2:$C$156,2,FALSE) -> 1
A6: 5 | B6: ALEJANDRA ALICIA FLORES CARLOS | C6: 5 | D6: Flores, Alejandra | E6: =VLOOKUP(C6,Tabla1[[id]:[EDAD]],4,FALSE) -> 61 | F6: =IF(Tabla1[[#This Row],[SEXO]]="Masculino",0,1) -> 1 | G6: =VLOOKUP(C6,Tabla1[[id]:[DISTRITO ]],6,FALSE) -> 2 | H6: =VLOOKUP(Tabla1[[#This Row],[PACTO POR EL QUE FUE ELECTO]],ref!$A$2:$B$8,2,FALSE) -> 5 | I6: =IF(Tabla1[[#This Row],[CAMBIO DE PACTO DURANTE CONVENCIÓN]]="",0,1) -> 1 | J6: =IF(Tabla1[[#This Row],[PUEBLO ORIGINARIO]]="",0,1) -> 0 | K6: =VLOOKUP(Tabla1[[#This Row],[LISTA EN LA CONVENCIÓN]],ref!A$11:B$21,2,FALSE) -> 6 | L6: 0 | M6: =VLOOKUP(C6,inp_ip_mp!$B$2:$C$156,2,FALSE) -> 0
A7: 6 | B7: ALEJANDRA PÍA PÉREZ ESPINA | C7: 6 | D7: Pérez, Alejandra | E7: =VLOOKUP(C7,Tabla1[[id]:[EDAD]],4,FALSE) -> 44 | F7: =IF(Tabla1[[#This Row],[SEXO]]="Masculino",0,1) -> 1 | G7: =VLOOKUP(C7,Tabla1[[id]:[DISTRITO ]],6,FALSE) -> 9 | H7: =VLOOKUP(Tabla1[[#This Row],[PACTO POR EL QUE FUE ELECTO]],ref!$A$2:$B$8,2,FALSE) -> 3 | I7: =IF(Tabla1[[#This Row],[CAMBIO DE PACTO DURANTE CONVENCIÓN]]="",0,1) -> 1 | J7: =IF(Tabla1[[#This Row],[PUEBLO ORIGINARIO]]="",0,1) -> 0 | K7: =VLOOKUP(Tabla1[[#This Row],[LISTA EN LA CONVENCIÓN]],ref!A$11:B$21,2,FALSE) -> 9 | L7: 0 | M7: =VLOOKUP(C7,inp_ip_mp!$B$2:$C$156,2,FALSE) -> 0
A8: 7 | B8: ALEXIS REINALDO CAIGUÁN ANCAPAN | C8: 7 | D8: Caiguan, Alexis | E8: =VLOOKUP(C8,Tabla1[[id]:[EDAD]],4,FALSE) -> 46 | F8: =IF(Tabla1[[#This Row],[SEXO]]="Masculino",0,1) -> 0 | G8: =VLOOKUP(C8,Tabla1[[id]:[DISTRITO ]],6,FALSE) -> 29 | H8: =VLOOKUP(Tabla1[[#This Row],[PACTO POR EL QUE FUE ELECTO]],ref!$A$2:$B$8,2,FALSE) -> 6 | I8: =IF(Tabla1[[#This Row],[CAMBIO DE PACTO DURANTE CONVENCIÓN]]="",0,1) -> 0 | J8: =IF(Tabla1[[#This Row],[PUEBLO ORIGINARIO]]="",0,1) -> 1 | K8: =VLOOKUP(Tabla1[[#This Row],[LISTA EN LA CONVENCIÓN]],ref!A$11:B$21,2,FALSE) -> 10 | L8: 17 | M8: =VLOOKUP(C8,inp_ip_mp!$B$2:$C$156,2,FALSE) -> 0
A9: 8 | B9: ALFREDO MORENO ECHEVERRÍA | C9: 8 | D9: Moreno, Alfredo | E9: =VLOOKUP(C9,Tabla1[[id]:[EDAD]],4,FALSE) -> 40 | F9: =IF(Tabla1[[#This Row],[SEXO]]="Masculino",0,1) -> 0 | G9: =VLOOKUP(C9,Tabla1[[id]:[DISTRITO ]],6,FALSE) -> 17 | H9: =VLOOKUP(Tabla1[[#This Row],[PACTO POR EL QUE FUE ELECTO]],ref!$A$2:$B$8,2,FALSE) -> 7 | I9: =IF(Tabla1[[#This Row],[CAMBIO DE PACTO DURANTE CONVENCIÓN]]="",0,1) -> 0 | J9: =IF(Tabla1[[#This Row],[PUEBLO ORIGINARIO]]="",0,1) -> 0 | K9: =VLOOKUP(Tabla1[[#This Row],[LISTA EN LA CONVENCIÓN]],ref!A$11:B$21,2,FALSE) -> 11 | L9: 0 | M9: =VLOOKUP(C9,inp_ip_mp!$B$2:$C$156,2,FALSE) -> 1
A10: 9 | B10: ALONDRA CARRILLO VIDAL | C10: 9 | D10: Carrillo, Alondra | E10: =VLOOKUP(C10,Tabla1[[id]:[EDAD]],4,FALSE) -> 31 | F10: =IF(Tabla1[[#This Row],[SEXO]]="Masculino",0,1) -> 1 | G10: =VLOOKUP(C10,Tabla1[[id]:[DISTRITO ]],6,FALSE) -> 12 | H10: =VLOOKUP(Tabla1[[#This Row],[PACTO POR EL QUE FUE ELECTO]],ref!$A$2:$B$8,2,FALSE) -> 5 | I10: =IF(Tabla1[[#This Row],[CAMBIO DE PACTO DURANTE CONVENCIÓN]]="",0,1) -> 1 | J10: =IF(Tabla1[[#This Row],[PUEBLO ORIGINARIO]]="",0,1) -> 0 | K10: =VLOOKUP(Tabla1[[#This Row],[LISTA EN LA CONVENCIÓN]],ref!A$11:B$21,2,FALSE) -> 6 | L10: 0 | M10: =VLOOKUP(C10,inp_ip_mp!$B$2:$C$156,2,FALSE) -> 0
A11: 10 | B11: ÁLVARO ARTURO JOFRE CÁCERES | C11: 10 | D11: Jofré, Alvaro | E11: =VLOOKUP(C11,Tabla1[[id]:[EDAD]],4,FALSE) -> 50 | F11: =IF(Tabla1[[#This Row],[SEXO]]="Masculino",0,1) -> 0 | G11: =VLOOKUP(C11,Tabla1[[id]:[DISTRITO ]],6,FALSE) -> 2 | H11: =VLOOKUP(Tabla1[[#This Row],[PACTO POR EL QUE FUE ELECTO]],ref!$A$2:$B$8,2,FALSE) -> 7 | I11: =IF(Tabla1[[#This Row],[CAMBIO DE PACTO DURANTE CONVENCIÓN]]="",0,1) -> 0 | J11: =IF(Tabla1[[#This Row],[PUEBLO ORIGINARIO]]="",0,1) -> 0 | K11: =VLOOKUP(Tabla1[[#This Row],[LISTA EN LA CONVENCIÓN]],ref!A$11:B$21,2,FALSE) -> 11 | L11: 7 | M11: =VLOOKUP(C11,inp_ip_mp!$B$2:$C$156,2,FALSE) -> 2
A12: 11 | B12: ALVIN ANTONIO SALDAÑA MUÑOZ | C12: 11 | D12: Saldaña, Alvin | E12: =VLOOKUP(C12,Tabla1[[id]:[EDAD]],4,FALSE) -> 45 | F12: =IF(Tabla1[[#This Row],[SEXO]]="Masculino",0,1) -> 0 | G12: =VLOOKUP(C12,Tabla1[[id]:[DISTRITO ]],6,FALSE) -> 15 | H12: =VLOOKUP(Tabla1[[#This Row],[PACTO POR EL QUE FUE ELECTO]],ref!$A$2:$B$8,2,FALSE) -> 5 | I12: =IF(Tabla1[[#This Row],[CAMBIO DE PACTO DURANTE CONVENCIÓN]]="",0,1) -> 1 | J12: =IF(Tabla1[[#This Row],[PUEBLO ORIGINARIO]]="",0,1) -> 0 | K12: =VLOOKUP(Tabla1[[#This Row],[LISTA EN LA CONVENCIÓN]],ref!A$11:B$21,2,FALSE) -> 6 | L12: 0 | M12: =VLOOKUP(C12,inp_ip_mp!$B$2:$C$156,2,FALSE) -> 0
A13: 12 | B13: AMAYA PAULINA ÁLVEZ MARIN | C13: 12 | D13: Alvez, Amaya | E13: =VLOOKUP(C13,Tabla1[[id]:[EDAD]],4,FALSE) -> 51 | F13: =IF(Tabla1[[#This Row],[SEXO]]="Masculino",0,1) -> 1 | G13: =VLOOKUP(C13,Tabla1[[id]:[DISTRITO ]],6,FALSE) -> 20 | H13: =VLOOKUP(Tabla1[[#This Row],[PACTO POR EL QUE FUE ELECTO]],ref!$A$2:$B$8,2,FALSE) -> 2 | I13: =IF(Tabla1[[#This Row],[CAMBIO DE PACTO DURANTE CONVENCIÓN]]="",0,1) -> 0 | J13: =IF(Tabla1[[#This Row],[PUEBLO ORIGINARIO]]="",0,1) -> 0 | K13: =VLOOKUP(Tabla1[[#This Row],[LISTA EN LA CONVENCIÓN]],ref!A$11:B$21,2,FALSE) -> 4 | L13: 8 | M13: =VLOOKUP(C13,inp_ip_mp!$B$2:$C$156,2,FALSE) -> 2
A14: 13 | B14: ANDRÉS NORBERTO CRUZ CARRASCO | C14: 13 | D14: Cruz, Andrés | E14: =VLOOKUP(C14,Tabla1[[id]:[EDAD]],4,FALSE) -> 48 | F14: =IF(Tabla1[[#This Row],[SEXO]]="Masculino",0,1) -> 0 | G14: =VLOOKUP(C14,Tabla1[[id]:[DISTRITO ]],6,FALSE) -> 20 | H14: =VLOOKUP(Tabla1[[#This Row],[PACTO POR EL QUE FUE ELECTO]],ref!$A$2:$B$8,2,FALSE) -> 1 | I14: =IF(Tabla1[[#This Row],[CAMBIO DE PACTO DURANTE CONVENCIÓN]]="",0,1) -> 0 | J14: =IF(Tabla1[[#This Row],[PUEBLO ORIGINARIO]]="",0,1) -> 0 | K14: =VLOOKUP(Tabla1[[#This Row],[LISTA EN LA CONVENCIÓN]],ref!A$11:B$21,2,FALSE) -> 3 | L14: 0 | M14: =VLOOKUP(C14,inp_ip_mp!$B$2:$C$156,2,FALSE) -> 1
... A156: 155 | B156: YARELA NICOHL GÓMEZ SÁNCHEZ | C156: 155 | D156: Gómez, Yarela | E156: =VLOOKUP(C156,Tabla1[[id]:[EDAD]],4,FALSE) -> 31 | F156: =IF(Tabla1[[#This Row],[SEXO]]="Masculino",0,1) -> 1 | G156: =VLOOKUP(C156,Tabla1[[id]:[DISTRITO ]],6,FALSE) -> 27 | H156: =VLOOKUP(Tabla1[[#This Row],[PACTO POR EL QUE FUE ELECTO]],ref!$A$2:$B$8,2,FALSE) -> 2 | I156: =IF(Tabla1[[#This Row],[CAMBIO DE PACTO DURANTE CONVENCIÓN]]="",0,1) -> 0 | J156: =IF(Tabla1[[#This Row],[PUEBLO ORIGINARIO]]="",0,1) -> 0 | K156: =VLOOKUP(Tabla1[[#This Row],[LISTA EN LA CONVENCIÓN]],ref!A$11:B$21,2,FALSE) -> 4 | L156: 0 | M156: =VLOOKUP(C156,inp_ip_mp!$B$2:$C$156,2,FALSE) -> 2

Sheet partidos_indep
A1: tipo partido o independ | G1: dummy_partido | H1: tag_partido | I1: partido
A2: COMUNISTA DE CHILE | B2: COMUNISTA | C2: DE | D2: CHILE | G2: =IF(B2="INDEPENDIENTE",0,1) -> 1 | H2: PC | I2: =IF(H2=0,0,G2) -> 1
A3: CONVERGENCIA SOCIAL | B3: CONVERGENCIA | C3: SOCIAL | G3: =IF(B3="INDEPENDIENTE",0,1) -> 1 | H3: CS | I3: =IF(H3=0,0,G2+G3) -> 2
A4: DEMOCRATA CRISTIANO | B4: DEMOCRATA | C4: CRISTIANO | G4: =IF(B4="INDEPENDIENTE",0,1) -> 1 | H4: DC | I4: =IF(H4=0,0,G2+G3+G4) -> 3
A5: EVOLUCION POLITICA | B5: EVOLUCION | C5: POLITICA | G5: =IF(B5="INDEPENDIENTE",0,1) -> 1 | H5: EVOPOLI | I5: =IF(H5=0,0,G2+G3+G4+G5) -> 4
A6: FEDERACION REGIONALISTA VERDE SOCIAL | B6: FEDERACION | C6: REGIONALISTA | D6: VERDE | E6: SOCIAL | G6: =IF(B6="INDEPENDIENTE",0,1) -> 1 | H6: FRVS | I6: =IF(H6=0,0,G2+G3+G4+G5+G6) -> 5
A7: INDEPENDIENTE | B7: INDEPENDIENTE | G7: =IF(B7="INDEPENDIENTE",0,1) -> 0 | H7: INDEPENDIENTE | I7: =IF(H7=0,0,G7) -> 0
A8: INDEPENDIENTE COMUNES | B8: INDEPENDIENTE | C8: COMUNES | G8: =IF(B8="INDEPENDIENTE",0,1) -> 0 | H8: INDEPENDIENTE | I8: 99
A9: INDEPENDIENTE COMUNISTA DE CHILE | B9: INDEPENDIENTE | C9: COMUNISTA | D9: DE | E9: CHILE | G9: =IF(B9="INDEPENDIENTE",0,1) -> 0 | H9: INDEPENDIENTE | I9: 98
A10: INDEPENDIENTE CONVERGENCIA SOCIAL | B10: INDEPENDIENTE | C10: CONVERGENCIA | D10: SOCIAL | G10: =IF(B10="INDEPENDIENTE",0,1) -> 0 | H10: INDEPENDIENTE | I10: =IF(H10=0,0,G7+G8+G9+G10) -> 0
A11: INDEPENDIENTE DEMOCRATA CRISTIANO | B11: INDEPENDIENTE | C11: DEMOCRATA | D11: CRISTIANO | G11: =IF(B11="INDEPENDIENTE",0,1) -> 0 | H11: INDEPENDIENTE | I11: =IF(H11=0,0,G7+G8+G9+G10+G11) -> 0
A12: INDEPENDIENTE EVOLUCION POLITICA | B12: INDEPENDIENTE | C12: EVOLUCION | D12: POLITICA | G12: =IF(B12="INDEPENDIENTE",0,1) -> 0 | H12: INDEPENDIENTE | I12: =IF(H12=0,0,G12) -> 0
A13: INDEPENDIENTE FEDERACION REGIONALISTA VERDE SOCIAL | B13: INDEPENDIENTE | C13: FEDERACION | D13: REGIONALISTA | E13: VERDE | F13: SOCIAL | G13: =IF(B13="INDEPENDIENTE",0,1) -> 0 | H13: INDEPENDIENTE | I13: =IF(H13=0,0,G12+G13) -> 0
A14: INDEPENDIENTE IGUALDAD | B14: INDEPENDIENTE | C14: IGUALDAD | G14: =IF(B14="INDEPENDIENTE",0,1) -> 0 | H14: INDEPENDIENTE | I14: =IF(H14=0,0,G12+G13+G14) -> 0
A15: INDEPENDIENTE LIBERAL DE CHILE | B15: INDEPENDIENTE | C15: LIBERAL | D15: DE | E15: CHILE | G15: =IF(B15="INDEPENDIENTE",0,1) -> 0 | H15: INDEPENDIENTE | I15: =IF(H15=0,0,G12+G13+G14+G15) -> 0
A16: INDEPENDIENTE POR LA DEMOCRACIA | B16: INDEPENDIENTE | C16: POR | D16: LA | E16: DEMOCRACIA | G16: =IF(B16="INDEPENDIENTE",0,1) -> 0 | H16: INDEPENDIENTE | I16: =IF(H16=0,0,G12+G13+G14+G15+G16) -> 0
A17: INDEPENDIENTE PROGRESISTA DE CHILE | B17: INDEPENDIENTE | C17: PROGRESISTA | D17: DE | E17: CHILE | G17: =IF(B17="INDEPENDIENTE",0,1) -> 0 | H17: INDEPENDIENTE | I17: =IF(H17=0,0,G17) -> 0
A18: INDEPENDIENTE RADICAL DE CHILE | B18: INDEPENDIENTE | C18: RADICAL | D18: DE | E18: CHILE | G18: =IF(B18="INDEPENDIENTE",0,1) -> 0 | H18: INDEPENDIENTE | I18: =IF(H18=0,0,G17+G18) -> 0
A19: INDEPENDIENTE RENOVACION NACIONAL | B19: INDEPENDIENTE | C19: RENOVACION | D19: NACIONAL | G19: =IF(B19="INDEPENDIENTE",0,1) -> 0 | H19: INDEPENDIENTE | I19: =IF(H19=0,0,G17+G18+G19) -> 0
A20: INDEPENDIENTE REVOLUCION DEMOCRATICA | B20: INDEPENDIENTE | C20: REVOLUCION | D20: DEMOCRATICA | G20: =IF(B20="INDEPENDIENTE",0,1) -> 0 | H20: INDEPENDIENTE | I20: =IF(H20=0,0,G17+G18+G19+G20) -> 0
A21: INDEPENDIENTE SOCIALISTA DE CHILE | B21: INDEPENDIENTE | C21: SOCIALISTA | D21: DE | E21: CHILE | G21: =IF(B21="INDEPENDIENTE",0,1) -> 0 | H21: INDEPENDIENTE | I21: =IF(H21=0,0,G17+G18+G19+G20+G21) -> 0
A22: INDEPENDIENTE UNION DEMOCRATA INDEPENDIENTE | B22: INDEPENDIENTE | C22: UNION | D22: DEMOCRATA | E22: INDEPENDIENTE | G22: =IF(B22="INDEPENDIENTE",0,1) -> 0 | H22: INDEPENDIENTE | I22: =IF(H22=0,0,G22) -> 0
A23: POR LA DEMOCRACIA | B23: POR | C23: LA | D23: DEMOCRACIA | G23: =IF(B23="INDEPENDIENTE",0,1) -> 1 | H23: PPD | I23: =IF(H23=0,0,SUM(G2:G23)) -> 6
A24: RENOVACION NACIONAL | B24: RENOVACION | C24: NACIONAL | G24: =IF(B24="INDEPENDIENTE",0,1) -> 1 | H24: RN | I24: =IF(H24=0,0,SUM(G2:G24)) -> 7
A25: REVOLUCION DEMOCRATICA | B25: REVOLUCION | C25: DEMOCRATICA | G25: =IF(B25="INDEPENDIENTE",0,1) -> 1 | H25: RD | I25: =IF(H25=0,0,SUM(G2:G25)) -> 8
A26: SOCIALISTA DE CHILE | B26: SOCIALISTA | C26: DE | D26: CHILE | G26: =IF(B26="INDEPENDIENTE",0,1) -> 1 | H26: PS | I26: =IF(H26=0,0,SUM(G2:G26)) -> 9
A27: UNION DEMOCRATA INDEPENDIENTE | B27: UNION | C27: DEMOCRATA | D27: INDEPENDIENTE | G27: =IF(B27="INDEPENDIENTE",0,1) -> 1 | H27: UDI | I27: =IF(H27=0,0,SUM(G2:G27)) -> 10
A28: PUEBLOS | G28: 0 | H28: PUEBLOS | I28: 17

Sheet ref
A1: pactos | B1: id_pactos
A2: APRUEBO | B2: 1
A3: APRUEBO DIGNIDAD | B3: 2
A4: DEL PUEBLO | B4: 3
A5: NUEVA CONSTITUCION | B5: 4
A6: OTROS | B6: 5
A7: PUEBLOS ORIGINARIOS | B7: 6
A8: VAMOS POR CHILE | B8: 7
A10: lista | B10: id_lista
A11: Chile Digno | B11: 1
A12: Colectivo Apruebo | B12: 2
A13: Colectivo Socialista | B13: 3
A14: Frente Amplio | B14: 4
A15: Mixto | B15: 5
A16: Movimiento Sociales Constituyentes | B16: 6
A17: Nueva Constitución | B17: 7
A18: Otros | B18: 8
A19: Pueblo Constituyente | B19: 9
A20: Pueblos Originarios | B20: 10
A21: Vamos por Chile | B21: 11
A23: PUEBLO ORIGINARIO | B23: id_alt_partidos
A24: AIMARA | B24: 11
A25: ATACAMEÑO | B25: 12
A26: CHANGO | B26: 13
A27: COLLA | B27: 14
A28: DIAGUITA | B28: 15
A29: KAWASHKAR | B29: 16
A30: MAPUCHE | B30: 17
A31: QUECHUA | B31: 18
A32: RAPANUI | B32: 19
A33: YAGAN | B33: 20

Sheet pacto
A1: nome_pactos | B1: pactos
A2: APRUEBO | B2: 1
A3: APRUEBO DIGNIDAD | B3: 2
A4: DEL PUEBLO | B4: 3
A5: NUEVA CONSTITUCION | B5: 4
A6: OTROS | B6: 5
A7: PUEBLOS ORIGINARIOS | B7: 6
A8: VAMOS POR CHILE | B8: 7

Sheet perfiles
A1: NOMBRE CONVENCIONAL CONSTITUYENTE | B1: id | C1: apellido, nombre | D1: FECHA DE NACIMIENTO | E1: EDAD | F1: SEXO | G1: DISTRITO | H1: PACTO POR EL QUE FUE ELECTO | I1: CAMBIO DE PACTO DURANTE CONVENCIÓN | J1: PUEBLO ORIGINARIO | K1: LISTA EN LA CONVENCIÓN | L1: PARTIDO POLÍTICO | M1: COMISIONES DE REGLAMENTOS DE LA CONVENCIÓN | N1: MIEMBRO COMISIÓN | O1: CAMBIO | P1: COMISIÓN DE SISTEMATIZACIÓN
A2: ADOLFO NONATO MILLABUR ÑANCUIL | B2: =VLOOKUP(Tabla1[[#This Row],[NOMBRE CONVENCIONAL CONSTITUYENTE]],all!$A$2:$B$156,2,FALSE) -> 1 | C2: =VLOOKUP(Tabla1[[#This Row],[id]],apellido_nombre!$J$2:$K$155,2,FALSE) -> Millabur, Adolfo | D2: 1966-08-30 | E2: 55 | F2: Masculino | G2: 29 | H2: PUEBLOS ORIGINARIOS | J2: MAPUCHE | K2: Pueblos Originarios | M2: Comisión de DD.HH, Verdad Histórica para la Justicia, Reparación y Garantías de no Repetición | N2: Forma de Estado | P2: Normas Transitorias
A3: ADRIANA CAMILA AMPUERO BARRIENTOS | B3: =VLOOKUP(Tabla1[[#This Row],[NOMBRE CONVENCIONAL CONSTITUYENTE]],all!$A$2:$B$156,2,FALSE) -> 2 | C3: =VLOOKUP(Tabla1[[#This Row],[id]],apellido_nombre!$J$2:$K$155,2,FALSE) -> Ampuero, Adriana | D3: 1986-12-01 | E3: 35 | F3: Femenino | G3: 26 | H3: DEL PUEBLO | I3: INDEPENDIENTE | K3: Otros | L3: INDEPENDIENTE | M3: Comisión Provisoria de Descentralización, Equidad y Justicia Territorial | N3: Forma de Estado | P3: Normas Transitorias
A4: ADRIANA JANET MERCEDES CANCINO MENESES | B4: =VLOOKUP(Tabla1[[#This Row],[NOMBRE CONVENCIONAL CONSTITUYENTE]],all!$A$2:$B$156,2,FALSE) -> 3 | C4: =VLOOKUP(Tabla1[[#This Row],[id]],apellido_nombre!$J$2:$K$155,2,FALSE) -> Cancino, Adriana | D4: 1962-06-22 | E4: 59 | F4: Femenino | G4: 16 | H4: APRUEBO | K4: Colectivo Socialista | L4: INDEPENDIENTE SOCIALISTA DE CHILE | M4: Comisión de Presupuestos y Administración Interior | N4: Derechos Fundamentales | P4: Preámbulo
A5: AGUSTÍN SQUELLA NARDUCCI | B5: =VLOOKUP(Tabla1[[#This Row],[NOMBRE CONVENCIONAL CONSTITUYENTE]],all!$A$2:$B$156,2,FALSE) -> 4 | C5: =VLOOKUP(Tabla1[[#This Row],[id]],apellido_nombre!$J$2:$K$155,2,FALSE) -> Squella, Agustín | D5: 1944-04-26 | E5: 78 | F5: Masculino | G5: 7 | H5: APRUEBO | K5: Colectivo Apruebo | L5: INDEPENDIENTE LIBERAL DE CHILE | M5: Comisión de Reglamentos | N5: Principios Constitucionales | P5: Armonización
A6: ALEJANDRA ALICIA FLORES CARLOS | B6: =VLOOKUP(Tabla1[[#This Row],[NOMBRE CONVENCIONAL CONSTITUYENTE]],all!$A$2:$B$156,2,FALSE) -> 5 | C6: =VLOOKUP(Tabla1[[#This Row],[id]],apellido_nombre!$J$2:$K$155,2,FALSE) -> Flores, Alejandra | D6: 1961-03-10 | E6: 61 | F6: Femenino | G6: 2 | H6: OTROS | I6: MOVIMIENTO SOCIALES CONSTITUYENTES | K6: Movimiento Sociales Constituyentes | L6: INDEPENDIENTE | M6: Comisión de Participación Popular y Equidad Territorial | N6: Sistema Político | P6: No participó
A7: ALEJANDRA PÍA PÉREZ ESPINA | B7: =VLOOKUP(Tabla1[[#This Row],[NOMBRE CONVENCIONAL CONSTITUYENTE]],all!$A$2:$B$156,2,FALSE) -> 6 | C7: =VLOOKUP(Tabla1[[#This Row],[id]],apellido_nombre!$J$2:$K$155,2,FALSE) -> Pérez, Alejandra | D7: 1977-10-25 | E7: 44 | F7: Femenino | G7: 9 | H7: DEL PUEBLO | I7: PUEBLO CONSTITUYENTE | K7: Pueblo Constituyente | L7: INDEPENDIENTE | M7: Comisión de Participación y Consulta Indígena | N7: Sistema Político | P7: No participó
A8: ALEXIS REINALDO CAIGUÁN ANCAPAN | B8: =VLOOKUP(Tabla1[[#This Row],[NOMBRE CONVENCIONAL CONSTITUYENTE]],all!$A$2:$B$156,2,FALSE) -> 7 | C8: =VLOOKUP(Tabla1[[#This Row],[id]],apellido_nombre!$J$2:$K$155,2,FALSE) -> Caiguan, Alexis | D8: 1975-08-18 | E8: 46 | F8: Masculino | G8: 29 | H8: PUEBLOS ORIGINARIOS | J8: MAPUCHE | K8: Pueblos Originarios | M8: Comisión de Participación y Consulta Indígena | N8: Sistemas de Conocimiento | P8: Normas Transitorias
A9: ALFREDO MORENO ECHEVERRÍA | B9: =VLOOKUP(Tabla1[[#This Row],[NOMBRE CONVENCIONAL CONSTITUYENTE]],all!$A$2:$B$156,2,FALSE) -> 8 | C9: =VLOOKUP(Tabla1[[#This Row],[id]],apellido_nombre!$J$2:$K$155,2,FALSE) -> Moreno, Alfredo | D9: 1982-02-11 | E9: 40 | F9: Masculino | G9: 17 | H9: VAMOS POR CHILE | K9: Vamos por Chile | L9: INDEPENDIENTE UNION DEMOCRATA INDEPENDIENTE | M9: Comisión Provisoria de Comunicaciones, Información y Transparencia | N9: Derechos Fundamentales | P9: No participó
A10: ALONDRA CARRILLO VIDAL | B10: =VLOOKUP(Tabla1[[#This Row],[NOMBRE CONVENCIONAL CONSTITUYENTE]],all!$A$2:$B$156,2,FALSE) -> 9 | C10: =VLOOKUP(Tabla1[[#This Row],[id]],apellido_nombre!$J$2:$K$155,2,FALSE) -> Carrillo, Alondra | D10: 1990-12-29 | E10: 31 | F10: Femenino | G10: 12 | H10: OTROS | I10: MOVIMIENTO SOCIALES CONSTITUYENTES | K10: Movimiento Sociales Constituyentes | L10: INDEPENDIENTE | M10: Comisión de Reglamentos | N10: Sistema Político | P10: Armonización
A11: ÁLVARO ARTURO JOFRE CÁCERES | B11: =VLOOKUP(Tabla1[[#This Row],[NOMBRE CONVENCIONAL CONSTITUYENTE]],all!$A$2:$B$156,2,FALSE) -> 10 | C11: =VLOOKUP(Tabla1[[#This Row],[id]],apellido_nombre!$J$2:$K$155,2,FALSE) -> Jofré, Alvaro | D11: 1971-10-16 | E11: 50 | F11: Masculino | G11: 2 | H11: VAMOS POR CHILE | K11: Vamos por Chile | L11: RENOVACION NACIONAL | M11: Comisión Provisoria de Descentralización, Equidad y Justicia Territorial | N11: Forma de Estado | P11: No participó
A12: ALVIN ANTONIO SALDAÑA MUÑOZ | B12: =VLOOKUP(Tabla1[[#This Row],[NOMBRE CONVENCIONAL CONSTITUYENTE]],all!$A$2:$B$156,2,FALSE) -> 11 | C12: =VLOOKUP(Tabla1[[#This Row],[id]],apellido_nombre!$J$2:$K$155,2,FALSE) -> Saldaña, Alvin | D12: 1976-07-05 | E12: 45 | F12: Masculino | G12: 15 | H12: OTROS | I12: MOVIMIENTO SOCIALES CONSTITUYENTES | K12: Movimiento Sociales Constituyentes | L12: INDEPENDIENTE | M12: Comisión Provisoria de Comunicaciones, Información y Transparencia | N12: Principios Constitucionales | P12: No participó
A13: AMAYA PAULINA ÁLVEZ MARIN | B13: =VLOOKUP(Tabla1[[#This Row],[NOMBRE CONVENCIONAL CONSTITUYENTE]],all!$A$2:$B$156,2,FALSE) -> 12 | C13: =VLOOKUP(Tabla1[[#This Row],[id]],apellido_nombre!$J$2:$K$155,2,FALSE) -> Alvez, Amaya | D13: 1971-04-03 | E13: 51 | F13: Femenino | G13: 20 | H13: APRUEBO DIGNIDAD | K13: Frente Amplio | L13: REVOLUCION DEMOCRATICA | M13: Comisión de Reglamentos | N13: Forma de Estado | P13: Armonización
A14: ANDRÉS NORBERTO CRUZ CARRASCO | B14: =VLOOKUP(Tabla1[[#This Row],[NOMBRE CONVENCIONAL CONSTITUYENTE]],all!$A$2:$B$156,2,FALSE) -> 13 | C14: =VLOOKUP(Tabla1[[#This Row],[id]],apellido_nombre!$J$2:$K$155,2,FALSE) -> Cruz, Andrés | D14: 1973-06-04 | E14: 48 | F14: Masculino | G14: 20 | H14: APRUEBO | K14: Colectivo Socialista | L14: INDEPENDIENTE SOCIALISTA DE CHILE | M14: Comunicaciones, Información y Transparencia | N14: Sistemas de Justicia | P14: Armonización
A15: AURORA GENOVEVA DELGADO VERGARA | B15: =VLOOKUP(Tabla1[[#This Row],[NOMBRE CONVENCIONAL CONSTITUYENTE]],all!$A$2:$B$156,2,FALSE) -> 14 | C15: =VLOOKUP(Tabla1[[#This Row],[id]],apellido_nombre!$J$2:$K$155,2,FALSE) -> Delgado, Aurora | D15: 1964-07-31 | E15: 57 | F15: Femenino | G15: 24 | H15: APRUEBO DIGNIDAD | K15: Frente Amplio | L15: INDEPENDIENTE REVOLUCION DEMOCRATICA | M15: Comisión de Participación Popular y Equidad Territorial | N15: Derechos Fundamentales | P15: No participó
A16: BÁRBARA ALEJANDRA REBOLLEDO AGUIRRE | B16: =VLOOKUP(Tabla1[[#This Row],[NOMBRE CONVENCIONAL CONSTITUYENTE]],all!$A$2:$B$156,2,FALSE) -> 15 | C16: =VLOOKUP(Tabla1[[#This Row],[id]],apellido_nombre!$J$2:$K$155,2,FALSE) -> Rebolledo, Bárbara | D16: 1973-01-22 | E16: 49 | F16: Femenino | G16: 17 | H16: VAMOS POR CHILE | K16: Vamos por Chile | L16: INDEPENDIENTE EVOLUCION POLITICA | M16: Comisión de Participación Popular y Equidad Territorial. | N16: Derechos Fundamentales | P16: No participó
A17: BÁRBARA SEPÚLVEDA HALES | B17: =VLOOKUP(Tabla1[[#This Row],[NOMBRE CONVENCIONAL CONSTITUYENTE]],all!$A$2:$B$156,2,FALSE) -> 16 | C17: =VLOOKUP(Tabla1[[#This Row],[id]],apellido_nombre!$J$2:$K$155,2,FALSE) -> Sepúlveda, Bárbara | D17: 1985-06-19 | E17: 36 | F17: Femenino | G17: 9 | H17: APRUEBO DIGNIDAD | K17: Chile Digno | L17: COMUNISTA DE CHILE | M17: Comisión de Reglamentos | N17: Sistema Político | P17: Armonización
A18: BASTIÁN ESTEBAN LABBÉ SALAZAR | B18: =VLOOKUP(Tabla1[[#This Row],[NOMBRE CONVENCIONAL CONSTITUYENTE]],all!$A$2:$B$156,2,FALSE) -> 17 | C18: =VLOOKUP(Tabla1[[#This Row],[id]],apellido_nombre!$J$2:$K$155,2,FALSE) -> Labbé, Bastián | D18: 1990-04-22 | E18: 32 | F18: Masculino | G18: 20 | H18: OTROS | I18: MOVIMIENTO SOCIALES CONSTITUYENTES | K18: Movimiento Sociales Constituyentes | L18: INDEPENDIENTE | M18: Comisión de Participación Popular y Equidad Territorial | N18: Forma de Estado | O18: Derechos Fundamentales | P18: No participó
A19: BEATRIZ DE JESUS SÁNCHEZ MUÑOZ | B19: =VLOOKUP(Tabla1[[#This Row],[NOMBRE CONVENCIONAL CONSTITUYENTE]],all!$A$2:$B$156,2,FALSE) -> 18 | C19: =VLOOKUP(Tabla1[[#This Row],[id]],apellido_nombre!$J$2:$K$155,2,FALSE) -> Sánchez, Beatriz | D19: 1970-12-24 | E19: 51 | F19: Femenino | G19: 12 | H19: APRUEBO DIGNIDAD | K19: Frente Amplio | L19: INDEPENDIENTE REVOLUCION DEMOCRATICA | M19: Comisión de Comunicaciones, Información y Transparencia | N19: Principios Constitucionales | P19: No participó
A20: BENITO JOSE BARANDA FERRAN | B20: =VLOOKUP(Tabla1[[#This Row],[NOMBRE CONVENCIONAL CONSTITUYENTE]],all!$A$2:$B$156,2,FALSE) -> 19 | C20: =VLOOKUP(Tabla1[[#This Row],[id]],apellido_nombre!$J$2:$K$155,2,FALSE) -> Baranda, Benito | D20: 1959-01-01 | E20: 63 | F20: Masculino | G20: 12 | H20: NUEVA CONSTITUCION | K20: Nueva Constitución | L20: INDEPENDIENTE | M20: Comisión de Ética | N20: Derechos Fundamentales | P20: No participó
A21: BERNARDO ARTURO DE LA MAZA BAÑADOS | B21: =VLOOKUP(Tabla1[[#This Row],[NOMBRE CONVENCIONAL CONSTITUYENTE]],all!$A$2:$B$156,2,FALSE) -> 20 | C21: =VLOOKUP(Tabla1[[#This Row],[id]],apellido_nombre!$J$2:$K$155,2,FALSE) -> De la Maza, Bernardo | D21: 1946-01-03 | E21: 76 | F21: Masculino | G21: 8 | H21: VAMOS POR CHILE | K21: Vamos por Chile | L21: INDEPENDIENTE EVOLUCION POLITICA | M21: Comisión de Ética | N21: Sistemas de Conocimiento | P21: No participó
A22: BERNARDO FONTAINE TALAVERA | B22: =VLOOKUP(Tabla1[[#This Row],[NOMBRE CONVENCIONAL CONSTITUYENTE]],all!$A$2:$B$156,2,FALSE) -> 21 | C22: =VLOOKUP(Tabla1[[#This Row],[id]],apellido_nombre!$J$2:$K$155,2,FALSE) -> Fontaine, Bernardo | D22: 1964-06-10 | E22: 57 | F22: Masculino | G22: 11 | H22: VAMOS POR CHILE | K22: Vamos por Chile | L22: INDEPENDIENTE RENOVACION NACIONAL | M22: Comisión de Presupuestos y Administración Interior | N22: Medio Ambiente | P22: No participó
A23: BESSY MIREYA DEL ROSARIO GALLARDO PRADO | B23: =VLOOKUP(Tabla1[[#This Row],[NOMBRE CONVENCIONAL CONSTITUYENTE]],all!$A$2:$B$156,2,FALSE) -> 22 | C23: =VLOOKUP(Tabla1[[#This Row],[id]],apellido_nombre!$J$2:$K$155,2,FALSE) -> Gallardo, Bessy | D23: 1984-12-31 | E23: 37 | F23: Femenino | G23: 8 | H23: APRUEBO | K23: Colectivo Apruebo | L23: INDEPENDIENTE PROGRESISTA DE CHILE | M23: Comisión de Ética | N23: Medio Ambiente | P23: Armonización
A24: CAMILA IGNACIA ZÁRATE ZÁRATE | B24: =VLOOKUP(Tabla1[[#This Row],[NOMBRE CONVENCIONAL CONSTITUYENTE]],all!$A$2:$B$156,2,FALSE) -> 23 | C24: =VLOOKUP(Tabla1[[#This Row],[id]],apellido_nombre!$J$2:$K$155,2,FALSE) -> Zárate, Camila | D24: 2001-08-12 | E24: 20 | F24: Femenino | G24: 7 | H24: DEL PUEBLO | I24: PUEBLO CONSTITUYENTE | K24: Pueblo Constituyente | L24: INDEPENDIENTE | M24: Comisión de Comunicaciones, Información y Transparencia. | N24: Medio Ambiente | P24: Normas Transitorias
A25: CARLOS MANUEL CALVO MUÑOZ | B25: =VLOOKUP(Tabla1[[#This Row],[NOMBRE CONVENCIONAL CONSTITUYENTE]],all!$A$2:$B$156,2,FALSE) -> 24 | C25: =VLOOKUP(Tabla1[[#This Row],[id]],apellido_nombre!$J$2:$K$155,2,FALSE) -> Calvo, Carlos | D25: 1946-03-07 | E25: 76 | F25: Masculino | G25: 5 | H25: APRUEBO | K25: Colectivo Socialista | L25: INDEPENDIENTE SOCIALISTA DE CHILE | M25: Comisión de Participación y Consulta Indígena | N25: Sistemas de Conocimiento | P25: No participó
A26: CARLOS MARTÍN ARRAU GARCÍA-HUIDOBRO | B26: =VLOOKUP(Tabla1[[#This Row],[NOMBRE CONVENCIONAL CONSTITUYENTE]],all!$A$2:$B$156,2,FALSE) -> 25 | C26: =VLOOKUP(Tabla1[[#This Row],[id]],apellido_nombre!$J$2:$K$155,2,FALSE) -> Arrau, Martín | D26: 1979-03-06 | E26: 43 | F26: Masculino | G26: 19 | H26: VAMOS POR CHILE | K26: Vamos por Chile | L26: UNION DEMOCRATA INDEPENDIENTE | M26: Comisión de Presupuestos y Administración Interior | N26: Principios Constitucionales | P26: Armonización
A27: CAROL CECILIA BOWN SEPÚLVEDA | B27: =VLOOKUP(Tabla1[[#This Row],[NOMBRE CONVENCIONAL CONSTITUYENTE]],all!$A$2:$B$156,2,FALSE) -> 26 | C27: =VLOOKUP(Tabla1[[#This Row],[id]],apellido_nombre!$J$2:$K$155,2,FALSE) -> Bown, Carol | D27: 1978-09-30 | E27: 43 | F27: Femenino | G27: 15 | H27: VAMOS POR CHILE | K27: Vamos por Chile | L27: UNION DEMOCRATA INDEPENDIENTE | M27: Comisión de Descentralización, Equidad y Justicia Territorial. | N27: Sistemas de Justicia | P27: Armonización
A28: CAROLINA ANDREA SEPÚLVEDA SEPÚLVEDA | B28: =VLOOKUP(Tabla1[[#This Row],[NOMBRE CONVENCIONAL CONSTITUYENTE]],all!$A$2:$B$156,2,FALSE) -> 27 | C28: =VLOOKUP(Tabla1[[#This Row],[id]],apellido_nombre!$J$2:$K$155,2,FALSE) -> Sepúlveda, Carolina | D28: 1981-07-03 | E28: 40 | F28: Femenino | G28: 19 | H28: NUEVA CONSTITUCION | K28: Nueva Constitución | L28: INDEPENDIENTE | M28: Comisión de Participación Popular y Equidad Territorial | N28: Medio Ambiente | P28: No participó
A29: CAROLINA CYNTIA VILCHES FUENZALIDA | B29: =VLOOKUP(Tabla1[[#This Row],[NOMBRE CONVENCIONAL CONSTITUYENTE]],all!$A$2:$B$156,2,FALSE) -> 28 | C29: =VLOOKUP(Tabla1[[#This Row],[id]],apellido_nombre!$J$2:$K$155,2,FALSE) -> Vilches, Carolina | D29: 1984-12-21 | E29: 37 | F29: Femenino | G29: 6 | H29: APRUEBO DIGNIDAD | I29: MOVIMIENTO SOCIALES CONSTITUYENTES | K29: Movimiento Sociales Constituyentes | L29: INDEPENDIENTE COMUNES | M29: Comisión de Reglamentos | N29: Medio Ambiente | P29: No participó
A30: CAROLINA ELIANA VIDELA OSORIO | B30: =VLOOKUP(Tabla1[[#This Row],[NOMBRE CONVENCIONAL CONSTITUYENTE]],all!$A$2:$B$156,2,FALSE) -> 29 | C30: =VLOOKUP(Tabla1[[#This Row],[id]],apellido_nombre!$J$2:$K$155,2,FALSE) -> Videla, Carolina | D30: 1968-12-22 | E30: 53 | F30: Femenino | G30: 1 | H30: APRUEBO DIGNIDAD | K30: Chile Digno | L30: COMUNISTA DE CHILE | M30: Comisión de Derechos Humanos, Verdad Histórica y Bases para la Justicia, Reparación y Garantías de no Repetición | N30: Sistemas de Conocimiento | P30: Preámbulo
A31: CÉSAR IGNACIO VALENZUELA MAASS | B31: =VLOOKUP(Tabla1[[#This Row],[NOMBRE CONVENCIONAL CONSTITUYENTE]],all!$A$2:$B$156,2,FALSE) -> 30 | C31: =VLOOKUP(Tabla1[[#This Row],[id]],apellido_nombre!$J$2:$K$155,2,FALSE) -> Valenzuela, César | D31: 1989-01-05 | E31: 33 | F31: Masculino | G31: 9 | H31: APRUEBO | K31: Colectivo Socialista | L31: SOCIALISTA DE CHILE | M31: Comisión de Presupuestos y Administración Interior | N31: Derechos Fundamentales | P31: Normas Transitorias
A32: CÉSAR RODRIGO URIBE ARAYA | B32: =VLOOKUP(Tabla1[[#This Row],[NOMBRE CONVENCIONAL CONSTITUYENTE]],all!$A$2:$B$156,2,FALSE) -> 31 | C32: =VLOOKUP(Tabla1[[#This Row],[id]],apellido_nombre!$J$2:$K$155,2,FALSE) -> Uribe, César | D32: 1984-01-18 | E32: 38 | F32: Masculino | G32: 19 | H32: DEL PUEBLO | I32: PUEBLO CONSTITUYENTE | K32: Pueblo Constituyente | L32: INDEPENDIENTE | M32: Comisión Provisoria de Descentralización, Equidad y Justicia Territorial | N32: Forma de Estado | P32: No participó
A33: CHRISTIAN PABLO VIERA ALVAREZ | B33: =VLOOKUP(Tabla1[[#This Row],[NOMBRE CONVENCIONAL CONSTITUYENTE]],all!$A$2:$B$156,2,FALSE) -> 32 | C33: =VLOOKUP(Tabla1[[#This Row],[id]],apellido_nombre!$J$2:$K$155,2,FALSE) -> Viera, Christian | D33: 1972-07-31 | E33: 49 | F33: Masculino | G33: 17 | H33: APRUEBO | K33: Frente Amplio | L33: INDEPENDIENTE DEMOCRATA CRISTIANO | M33: Comisión de Ética | N33: Sistemas de Justicia | P33: Armonización
A34: CLAUDIA MABEL CASTRO GUTIÉRREZ | B34: =VLOOKUP(Tabla1[[#This Row],[NOMBRE CONVENCIONAL CONSTITUYENTE]],all!$A$2:$B$156,2,FALSE) -> 33 | C34: =VLOOKUP(Tabla1[[#This Row],[id]],apellido_nombre!$J$2:$K$155,2,FALSE) -> Castro, Claudia | D34: 1968-04-28 | E34: 54 | F34: Femenino | G34: 14 | H34: VAMOS POR CHILE | K34: Vamos por Chile | L34: INDEPENDIENTE UNION DEMOCRATA INDEPENDIENTE | M34: Comisión de Participación Popular y Equidad Territorial | N34: Derechos Fundamentales | P34: No participó
A35: CLAUDIA MARGARITA LETELIER CORTÉS | B35: =VLOOKUP(Tabla1[[#This Row],[NOMBRE CONVENCIONAL CONSTITUYENTE]],all!$A$2:$B$156,2,FALSE) -> 34 | C35: =VLOOKUP(Tabla1[[#This Row],[id]],apellido_nombre!$J$2:$K$155,2,FALSE) -> Letelier, Margarita | D35: 1981-05-10 | E35: 41 | F35: Femenino | G35: 17 | H35: VAMOS POR CHILE | K35: Vamos por Chile | L35: UNION DEMOCRATA INDEPENDIENTE | M35: Comisión de Derechos Humanos, Verdad Histórica y Bases para la Justicia, Reparación y Garantías de no Repetición | N35: Sistemas de Conocimiento | P35: No participó
A36: CLAUDIO FRANCISCO GÓMEZ CASTRO | B36: =VLOOKUP(Tabla1[[#This Row],[NOMBRE CONVENCIONAL CONSTITUYENTE]],all!$A$2:$B$156,2,FALSE) -> 35 | C36: =VLOOKUP(Tabla1[[#This Row],[id]],apellido_nombre!$J$2:$K$155,2,FALSE) -> Gómez, Claudio | D36: 1977-12-10 | E36: 44 | F36: Masculino | G36: 6 | H36: APRUEBO | K36: Colectivo Socialista | L36: INDEPENDIENTE SOCIALISTA DE CHILE | M36: Comisión de Reglamentos | N36: Forma de Estado | P36: Armonización
A37: CONSTANZA ANDREA SAN JUAN STANDEN | B37: =VLOOKUP(Tabla1[[#This Row],[NOMBRE CONVENCIONAL CONSTITUYENTE]],all!$A$2:$B$156,2,FALSE) -> 36 | C37: =VLOOKUP(Tabla1[[#This Row],[id]],apellido_nombre!$J$2:$K$155,2,FALSE) -> San Juan, Constanza | D37: 1985-09-18 | E37: 36 | F37: Femenino | G37: 4 | H37: DEL PUEBLO | I37: MOVIMIENTO SOCIALES CONSTITUYENTES | K37: Movimiento Sociales Constituyentes | L37: INDEPENDIENTE | M37: Comisión de Derechos Humanos, Verdad Histórica y Bases para la Justicia, Reparación y Garantías de no Repetición | N37: Medio Ambiente | P37: No participó
A38: CONSTANZA GABRIELA SCHONHAUT SOTO | B38: =VLOOKUP(Tabla1[[#This Row],[NOMBRE CONVENCIONAL CONSTITUYENTE]],all!$A$2:$B$156,2,FALSE) -> 37 | C38: =VLOOKUP(Tabla1[[#This Row],[id]],apellido_nombre!$J$2:$K$155,2,FALSE) -> Schonhaut, Constanza | D38: 1989-01-31 | E38: 33 | F38: Femenino | G38: 11 | H38: APRUEBO DIGNIDAD | K38: Frente Amplio | L38: CONVERGENCIA SOCIAL | M38: Comisión de Participación Popular y Equidad Territorial | N38: Sistema Político | P38: Normas Transitorias
A39: CONSTANZA VERÓNICA HUBE PORTUS | B39: =VLOOKUP(Tabla1[[#This Row],[NOMBRE CONVENCIONAL CONSTITUYENTE]],all!$A$2:$B$156,2,FALSE) -> 38 | C39: =VLOOKUP(Tabla1[[#This Row],[id]],apellido_nombre!$J$2:$K$155,2,FALSE) -> Hube, Constanza | D39: 1986-03-10 | E39: 36 | F39: Femenino | G39: 11 | H39: VAMOS POR CHILE | K39: Vamos por Chile | L39: UNION DEMOCRATA INDEPENDIENTE | M39: Comisión de Reglamentos | N39: Sistema Político | P39: Normas Transitorias
A40: CRISTIÁN MONCKEBERG BRUNER | B40: =VLOOKUP(Tabla1[[#This Row],[NOMBRE CONVENCIONAL CONSTITUYENTE]],all!$A$2:$B$156,2,FALSE) -> 39 | C40: =VLOOKUP(Tabla1[[#This Row],[id]],apellido_nombre!$J$2:$K$155,2,FALSE) -> Monckeberg, Cristían | D40: 1968-05-12 | E40: 53 | F40: Masculino | G40: 10 | H40: VAMOS POR CHILE | K40: Vamos por Chile | L40: RENOVACION NACIONAL | M40: Comisión de Comunicaciones, Información y Transparencia. | N40: Sistema Político | P40: Normas Transitorias
...

Sheet VOTACIONES POR INFORME Y NS
A1: Convencional | B1: Informe Comisión | C1: % votaciones A Favor | D1: % votaciones En Contra | E1: % votaciones Abstención | F1: % votaciones No Votó | G1: Nº A Favor | H1: Nº En Contra | I1: Nº Abstención | J1: Nº No votó | K1: Nº de Votaciones | L1: Partido | M1: Nominate Score General | N1: NS Convencional por votación de informe de comisión
A2: Zúñiga, Luis Arturo | B2: Sistema Político | C2: 0.2716763 | D2: 0.47591522 | E2: 0.2177264 | F2: 0.034682081 | G2: 141 | H2: 247 | I2: 113 | J2: 18 | K2: 519 | L2: Vamos por Chile | M2: 0.85652316 | N2: -0.94686896
B3: Principios Constitucionales | C3: 0.26023392 | D3: 0.50877193 | E3: 0.21345029 | F3: 0.01754386 | G3: 89 | H3: 174 | I3: 73 | J3: 6 | K3: 342 | N3: -0.8718366
B4: Medio Ambiente | C4: 0.22881356 | D4: 0.55932203 | E4: 0.19491525 | F4: 0.016949153 | G4: 54 | H4: 132 | I4: 46 | J4: 4 | K4: 236 | N4: -0.76463825
B5: Justicia | C5: 0.23037975 | D5: 0.4835443 | E5: 0.27594937 | F5: 0.010126582 | G5: 91 | H5: 191 | I5: 109 | J5: 4 | K5: 395 | N5: -0.96333051
B6: Forma de Estado | C6: 0.25044092 | D6: 0.45149912 | E6: 0.24514991 | F6: 0.052910053 | G6: 142 | H6: 256 | I6: 139 | J6: 30 | K6: 567 | N6: -0.45570508
B7: Derechos Fundamentales | C7: 0.53125 | D7: 0.29769737 | E7: 0.14638158 | F7: 0.024671053 | G7: 323 | H7: 181 | I7: 89 | J7: 15 | K7: 608 | N7: -0.8348648
B8: Conocimiento | C8: 0.26190476 | D8: 0.4702381 | E8: 0.26190476 | F8: 0.005952381 | G8: 88 | H8: 158 | I8: 88 | J8: 2 | K8: 336 | N8: -0.85686088
A9: Zárate, Camila | B9: Sistema Político | C9: 0.49903661 | D9: 0.43545279 | E9: 0.019267823 | F9: 0.046242775 | G9: 259 | H9: 226 | I9: 10 | J9: 24 | K9: 519 | L9: Pueblo Constituyente | M9: -0.8856073 | N9: 0.66718769
B10: Principios Constitucionales | C10: 0.69883041 | D10: 0.23684211 | E10: 0.035087719 | F10: 0.029239766 | G10: 239 | H10: 81 | I10: 12 | J10: 10 | K10: 342 | N10: 0.941845
B11: Medio Ambiente | C11: 0.72457627 | D11: 0.21610169 | E11: 0.046610169 | F11: 0.012711864 | G11: 171 | H11: 51 | I11: 11 | J11: 3 | K11: 236 | N11: 0.564062
B12: Justicia | C12: 0.74177215 | D12: 0.17468354 | E12: 0.053164557 | F12: 0.030379747 | G12: 293 | H12: 69 | I12: 21 | J12: 12 | K12: 395 | N12: 0.75080001
B13: Forma de Estado | C13: 0.75308642 | D13: 0.14109347 | E13: 0.074074074 | F13: 0.031746032 | G13: 427 | H13: 80 | I13: 42 | J13: 18 | K13: 567 | N13: 0.76415354
B14: Derechos Fundamentales | C14: 0.32565789 | D14: 0.56743421 | E14: 0.060855263 | F14: 0.046052632 | G14: 198 | H14: 345 | I14: 37 | J14: 28 | K14: 608 | N14: 0.91732675
B15: Conocimiento | C15: 0.63095238 | D15: 0.23809524 | E15: 0.089285714 | F15: 0.041666667 | G15: 212 | H15: 80 | I15: 30 | J15: 14 | K15: 336 | N15: 0.86803728
A16: Woldarsky, Manuel | B16: Sistema Político | C16: 0.59537572 | D16: 0.37379576 | E16: 0.0019267823 | F16: 0.028901734 | G16: 309 | H16: 194 | I16: 1 | J16: 15 | K16: 519 | L16: Mixto | M16: -0.92628521 | N16: 0.90230042
B17: Principios Constitucionales | C17: 0.62573099 | D17: 0.34795322 | E17: 0.0058479532 | F17: 0.020467836 | G17: 214 | H17: 119 | I17: 2 | J17: 7 | K17: 342 | N17: 0.7380482
B18: Medio Ambiente | C18: 0.76694915 | D18: 0.21610169 | E18: 0.0042372881 | F18: 0.012711864 | G18: 181 | H18: 51 | I18: 1 | J18: 3 | K18: 236 | N18: 0.47878626
B19: Justicia | C19: 0.77721519 | D19: 0.17974684 | E19: 0.040506329 | F19: 0.0025316456 | G19: 307 | H19: 71 | I19: 16 | J19: 1 | K19: 395 | N19: 0.95661807
B20: Forma de Estado | C20: 0.79717813 | D20: 0.17636684 | E20: 0.0052910053 | F20: 0.021164021 | G20: 452 | H20: 100 | I20: 3 | J20: 12 | K20: 567 | N20: 0.7660712
B21: Derechos Fundamentales | C21: 0.45394737 | D21: 0.50328947 | E21: 0.0016447368 | F21: 0.041118421 | G21: 276 | H21: 306 | I21: 1 | J21: 25 | K21: 608 | N21: 0.93088359
B22: Conocimiento | C22: 0.71130952 | D22: 0.25297619 | E22: 0.017857143 | F22: 0.017857143 | G22: 239 | H22: 85 | I22: 6 | J22: 6 | K22: 336 | N22: 0.96969736
A23: Villena, Ingrid | B23: Sistema Político | C23: 0.46820809 | D23: 0.34296724 | E23: 0.013487476 | F23: 0.17533719 | G23: 243 | H23: 178 | I23: 7 | J23: 91 | K23: 519 | L23: Pueblo Constituyente | M23: -0.79295927 | N23: 0.80420071
B24: Principios Constitucionales | C24: 0.65789474 | D24: 0.28947368 | E24: 0.029239766 | F24: 0.023391813 | G24: 225 | H24: 99 | I24: 10 | J24: 8 | K24: 342 | N24: 0.73439163
B25: Medio Ambiente | C25: 0.71610169 | D25: 0.21186441 | E25: 0.050847458 | F25: 0.021186441 | G25: 169 | H25: 50 | I25: 12 | J25: 5 | K25: 236 | N25: 0.31749222
B26: Justicia | C26: 0.75949367 | D26: 0.20759494 | E26: 0.030379747 | F26: 0.0025316456 | G26: 300 | H26: 82 | I26: 12 | J26: 1 | K26: 395 | N26: 0.66571796
B27: Forma de Estado | C27: 0.70546737 | D27: 0.17283951 | E27: 0.093474427 | F27: 0.028218695 | G27: 400 | H27: 98 | I27: 53 | J27: 16 | K27: 567 | N27: 0.69983351
B28: Derechos Fundamentales | C28: 0.375 | D28: 0.57565789 | E28: 0.034539474 | F28: 0.014802632 | G28: 228 | H28: 350 | I28: 21 | J28: 9 | K28: 608 | N28: 0.74627507
B29: Conocimiento | C29: 0.64285714 | D29: 0.27678571 | E29: 0.05952381 | F29: 0.020833333 | G29: 216 | H29: 93 | I29: 20 | J29: 7 | K29: 336 | N29: 0.74622607
A30: Vilches, Carolina | B30: Sistema Político | C30: 0.51445087 | D30: 0.44123314 | E30: 0.013487476 | F30: 0.030828516 | G30: 267 | H30: 229 | I30: 7 | J30: 16 | K30: 519 | L30: Movimiento Sociales Constituyentes | M30: -0.89286345 | N30: 0.60433555
B31: Principios Constitucionales | C31: 0.6871345 | D31: 0.27777778 | E31: 0.0058479532 | F31: 0.029239766 | G31: 235 | H31: 95 | I31: 2 | J31: 10 | K31: 342 | N31: 0.82121426
B32: Medio Ambiente | C32: 0.72033898 | D32: 0.21186441 | E32: 0.042372881 | F32: 0.025423729 | G32: 170 | H32: 50 | I32: 10 | J32: 6 | K32: 236 | N32: 0.37460175
B33: Justicia | C33: 0.76708861 | D33: 0.15696203 | E33: 0.04556962 | F33: 0.030379747 | G33: 303 | H33: 62 | I33: 18 | J33: 12 | K33: 395 | N33: 0.81670636
B34: Forma de Estado | C34: 0.82010582 | D34: 0.14462081 | E34: 0.0070546737 | F34: 0.028218695 | G34: 465 | H34: 82 | I34: 4 | J34: 16 | K34: 567 | N34: 0.99722695
B35: Derechos Fundamentales | C35: 0.40460526 | D35: 0.53947368 | E35: 0.021381579 | F35: 0.034539474 | G35: 246 | H35: 328 | I35: 13 | J35: 21 | K35: 608 | N35: 0.98053402
B36: Conocimiento | C36: 0.69345238 | D36: 0.23511905 | E36: 0.035714286 | F36: 0.035714286 | G36: 233 | H36: 79 | I36: 12 | J36: 12 | K36: 336 | N36: 0.92296469
A37: Viera, Christian | B37: Sistema Político | C37: 0.47976879 | D37: 0.41618497 | E37: 0.038535645 | F37: 0.065510597 | G37: 249 | H37: 216 | I37: 20 | J37: 34 | K37: 519 | L37: Frente Amplio | M37: -0.47713217 | N37: 0.46622667
B38: Principios Constitucionales | C38: 0.46491228 | D38: 0.46491228 | E38: 0.067251462 | F38: 0.0029239766 | G38: 159 | H38: 159 | I38: 23 | J38: 1 | K38: 342 | N38: 0.43688056
B39: Medio Ambiente | C39: 0.22457627 | D39: 0.61016949 | E39: 0.15677966 | F39: 0.0084745763 | G39: 53 | H39: 144 | I39: 37 | J39: 2 | K39: 236 | N39: -0.26786399
B40: Justicia | C40: 0.72405063 | D40: 0.24810127 | E40: 0.02278481 | F40: 0.0050632911 | G40: 286 | H40: 98 | I40: 9 | J40: 2 | K40: 395 | N40: 0.5038417
...

Sheet apellido_nombre
A1: apellido, nombre | B1: draft_apell | C1: draft_nombre | D1: arrumar_apellido | E1: arrumar_nombre | F1: 1er apell | G1: 1er nombr | H1: minuscula | I1: sin accento | J1: id | K1: apellido, nombre | L1: id
A2: Millabur, Adolfo | B2: {=_xlfn.TEXTSPLIT(A2,",")} -> #NAME? | C2: #NAME? | D2: =TRIM(B2) -> #NAME? | E2: =TRIM(C2) -> #NAME? | F2: =LOWER(D2) -> #NAME? | G2: =LOWER(E2) -> #NAME? | H2: =LOWER(A2) -> millabur, adolfo | I2: millabur, adolfo | J2: =VLOOKUP(I2,all!$N$2:$O$156,2,FALSE) -> 1 | K2: Millabur, Adolfo | L2: 1
A3: Ampuero, Adriana | B3: {=_xlfn.TEXTSPLIT(A3,",")} -> #NAME? | C3: #NAME? | D3: =TRIM(B3) -> #NAME? | E3: =TRIM(C3) -> #NAME? | F3: =LOWER(D3) -> #NAME? | G3: =LOWER(E3) -> #NAME? | H3: =LOWER(A3) -> ampuero, adriana | I3: ampuero, adriana | J3: =VLOOKUP(I3,all!$N$2:$O$156,2,FALSE) -> 2 | K3: Ampuero, Adriana | L3: 2
A4: Cancino, Adriana | B4: {=_xlfn.TEXTSPLIT(A4,",")} -> #NAME? | C4: #NAME? | D4: =TRIM(B4) -> #NAME? | E4: =TRIM(C4) -> #NAME? | F4: =LOWER(D4) -> #NAME? | G4: =LOWER(E4) -> #NAME? | H4: =LOWER(A4) -> cancino, adriana | I4: cancino, adriana | J4: =VLOOKUP(I4,all!$N$2:$O$156,2,FALSE) -> 3 | K4: Cancino, Adriana | L4: 3
A5: Squella, Agustín | B5: {=_xlfn.TEXTSPLIT(A5,",")} -> #NAME? | C5: #NAME? | D5: =TRIM(B5) -> #NAME? | E5: =TRIM(C5) -> #NAME? | F5: =LOWER(D5) -> #NAME? | G5: =LOWER(E5) -> #NAME? | H5: =LOWER(A5) -> squella, agustín | I5: squella, agustin | J5: =VLOOKUP(I5,all!$N$2:$O$156,2,FALSE) -> 4 | K5: Squella, Agustín | L5: 4
A6: Flores, Alejandra | B6: {=_xlfn.TEXTSPLIT(A6,",")} -> #NAME? | C6: #NAME? | D6: =TRIM(B6) -> #NAME? | E6: =TRIM(C6) -> #NAME? | F6: =LOWER(D6) -> #NAME? | G6: =LOWER(E6) -> #NAME? | H6: =LOWER(A6) -> flores, alejandra | I6: flores, alejandra | J6: =VLOOKUP(I6,all!$N$2:$O$156,2,FALSE) -> 5 | K6: Flores, Alejandra | L6: 5
A7: Pérez, Alejandra | B7: {=_xlfn.TEXTSPLIT(A7,",")} -> #NAME? | C7: #NAME? | D7: =TRIM(B7) -> #NAME? | E7: =TRIM(C7) -> #NAME? | F7: =LOWER(D7) -> #NAME? | G7: =LOWER(E7) -> #NAME? | H7: =LOWER(A7) -> pérez, alejandra | I7: perez, alejandra | J7: =VLOOKUP(I7,all!$N$2:$O$156,2,FALSE) -> 6 | K7: Pérez, Alejandra | L7: 6
A8: Caiguan, Alexis | B8: {=_xlfn.TEXTSPLIT(A8,",")} -> #NAME? | C8: #NAME? | D8: =TRIM(B8) -> #NAME? | E8: =TRIM(C8) -> #NAME? | F8: =LOWER(D8) -> #NAME? | G8: =LOWER(E8) -> #NAME? | H8: =LOWER(A8) -> caiguan, alexis | I8: caiguan, alexis | J8: =VLOOKUP(I8,all!$N$2:$O$156,2,FALSE) -> 7 | K8: Caiguan, Alexis | L8: 7
A9: Moreno, Alfredo | B9: {=_xlfn.TEXTSPLIT(A9,",")} -> #NAME? | C9: #NAME? | D9: =TRIM(B9) -> #NAME? | E9: =TRIM(C9) -> #NAME? | F9: =LOWER(D9) -> #NAME? | G9: =LOWER(E9) -> #NAME? | H9: =LOWER(A9) -> moreno, alfredo | I9: moreno, alfredo | J9: =VLOOKUP(I9,all!$N$2:$O$156,2,FALSE) -> 8 | K9: Moreno, Alfredo | L9: 8
A10: Carrillo, Alondra | B10: {=_xlfn.TEXTSPLIT(A10,",")} -> #NAME? | C10: #NAME? | D10: =TRIM(B10) -> #NAME? | E10: =TRIM(C10) -> #NAME? | F10: =LOWER(D10) -> #NAME? | G10: =LOWER(E10) -> #NAME? | H10: =LOWER(A10) -> carrillo, alondra | I10: carrillo, alondra | J10: =VLOOKUP(I10,all!$N$2:$O$156,2,FALSE) -> 9 | K10: Carrillo, Alondra | L10: 9
A11: Jofré, Alvaro | B11: {=_xlfn.TEXTSPLIT(A11,",")} -> #NAME? | C11: #NAME? | D11: =TRIM(B11) -> #NAME? | E11: =TRIM(C11) -> #NAME? | F11: =LOWER(D11) -> #NAME? | G11: =LOWER(E11) -> #NAME? | H11: =LOWER(A11) -> jofré, alvaro | I11: jofre, alvaro | J11: =VLOOKUP(I11,all!$N$2:$O$156,2,FALSE) -> 10 | K11: Jofré, Alvaro | L11: 10
A12: Saldaña, Alvin | B12: {=_xlfn.TEXTSPLIT(A12,",")} -> #NAME? | C12: #NAME? | D12: =TRIM(B12) -> #NAME? | E12: =TRIM(C12) -> #NAME? | F12: =LOWER(D12) -> #NAME? | G12: =LOWER(E12) -> #NAME? | H12: =LOWER(A12) -> saldaña, alvin | I12: saldana, alvin | J12: =VLOOKUP(I12,all!$N$2:$O$156,2,FALSE) -> 11 | K12: Saldaña, Alvin | L12: 11
A13: Alvez, Amaya | B13: {=_xlfn.TEXTSPLIT(A13,",")} -> #NAME? | C13: #NAME? | D13: =TRIM(B13) -> #NAME? | E13: =TRIM(C13) -> #NAME? | F13: =LOWER(D13) -> #NAME? | G13: =LOWER(E13) -> #NAME? | H13: =LOWER(A13) -> alvez, amaya | I13: alvez, amaya | J13: =VLOOKUP(I13,all!$N$2:$O$156,2,FALSE) -> 12 | K13: Alvez, Amaya | L13: 12
... A155: Gómez, Yarela | B155: {=_xlfn.TEXTSPLIT(A155,",")} -> #NAME? | C155: #NAME? | D155: =TRIM(B155) -> #NAME? | E155: =TRIM(C155) -> #NAME? | F155: =LOWER(D155) -> #NAME? | G155: =LOWER(E155) -> #NAME? | H155: =LOWER(A155) -> gómez, yarela | I155: gomez, yarela | J155: =VLOOKUP(I155,all!$N$2:$O$156,2,FALSE) -> 155 | K155: Gómez, Yarela | L155: 155

Sheet all
A1: nombre completo | B1: id | C1: 1er nombre | D1: 2o nombre | E1: 1er apellido | F1: 2o apellido | I1: count | J1: check | K1: 1er nombre | L1: 1er apellido | M1: apellido, nombre | N1: sin acento | O1: id
A2: ADOLFO NONATO MILLABUR ÑANCUIL | B2: 1 | C2: {=_xlfn.TEXTSPLIT(A2," ")} -> #NAME? | D2: #NAME? | E2: #NAME? | F2: #NAME? | I2: =COUNTA(C2:H2) -> 4 | J2: =IF(I2<5,1,0) -> 1 | K2: =LOWER(TRIM(C2)) -> #NAME? | L2: =LOWER(TRIM(E2)) -> #NAME? | M2: =IFERROR(IF(J2=1,_xlfn.CONCAT(L2,", ",K2)),0) -> 0 | N2: millabur, adolfo | O2: =B2 -> 1
A3: ADRIANA CAMILA AMPUERO BARRIENTOS | B3: 2 | C3: {=_xlfn.TEXTSPLIT(A3," ")} -> #NAME? | D3: #NAME? | E3: #NAME? | F3: #NAME? | I3: =COUNTA(C3:H3) -> 4 | J3: =IF(I3<5,1,0) -> 1 | K3: =LOWER(TRIM(C3)) -> #NAME? | L3: =LOWER(TRIM(E3)) -> #NAME? | M3: =IFERROR(IF(J3=1,_xlfn.CONCAT(L3,", ",K3)),0) -> 0 | N3: ampuero, adriana | O3: =B3 -> 2
A4: ADRIANA JANET MERCEDES CANCINO MENESES | B4: 3 | C4: ADRIANA | D4: JANET | E4: CANCINO | F4: MENESES | I4: =COUNTA(C4:H4) -> 4 | J4: =IF(I4<5,1,0) -> 1 | K4: =LOWER(TRIM(C4)) -> adriana | L4: =LOWER(TRIM(E4)) -> cancino | M4: =IFERROR(IF(J4=1,_xlfn.CONCAT(L4,", ",K4)),0) -> 0 | N4: cancino, adriana | O4: =B4 -> 3
A5: AGUSTÍN SQUELLA NARDUCCI | B5: 4 | C5: AGUSTÍN | D5: SQUELLA | E5: SQUELLA | F5: NARDUCCI | I5: =COUNTA(C5:H5) -> 4 | J5: =IF(I5<5,1,0) -> 1 | K5: =LOWER(TRIM(C5)) -> agustín | L5: =LOWER(TRIM(E5)) -> squella | M5: =IFERROR(IF(J5=1,_xlfn.CONCAT(L5,", ",K5)),0) -> 0 | N5: squella, agustin | O5: =B5 -> 4
A6: ALEJANDRA ALICIA FLORES CARLOS | B6: 5 | C6: {=_xlfn.TEXTSPLIT(A6," ")} -> #NAME? | D6: #NAME? | E6: #NAME? | F6: #NAME? | I6: =COUNTA(C6:H6) -> 4 | J6: =IF(I6<5,1,0) -> 1 | K6: =LOWER(TRIM(C6)) -> #NAME? | L6: =LOWER(TRIM(E6)) -> #NAME? | M6: =IFERROR(IF(J6=1,_xlfn.CONCAT(L6,", ",K6)),0) -> 0 | N6: flores, alejandra | O6: =B6 -> 5
A7: ALEJANDRA PÍA PÉREZ ESPINA | B7: 6 | C7: {=_xlfn.TEXTSPLIT(A7," ")} -> #NAME? | D7: #NAME? | E7: #NAME? | F7: #NAME? | I7: =COUNTA(C7:H7) -> 4 | J7: =IF(I7<5,1,0) -> 1 | K7: =LOWER(TRIM(C7)) -> #NAME? | L7: =LOWER(TRIM(E7)) -> #NAME? | M7: =IFERROR(IF(J7=1,_xlfn.CONCAT(L7,", ",K7)),0) -> 0 | N7: perez, alejandra | O7: =B7 -> 6
A8: ALEXIS REINALDO CAIGUÁN ANCAPAN | B8: 7 | C8: {=_xlfn.TEXTSPLIT(A8," ")} -> #NAME? | D8: #NAME? | E8: #NAME? | F8: #NAME? | I8: =COUNTA(C8:H8) -> 4 | J8: =IF(I8<5,1,0) -> 1 | K8: =LOWER(TRIM(C8)) -> #NAME? | L8: =LOWER(TRIM(E8)) -> #NAME? | M8: =IFERROR(IF(J8=1,_xlfn.CONCAT(L8,", ",K8)),0) -> 0 | N8: caiguan, alexis | O8: =B8 -> 7
A9: ALFREDO MORENO ECHEVERRÍA | B9: 8 | C9: ALFREDO | D9: MORENO | E9: MORENO | I9: =COUNTA(C9:H9) -> 3 | J9: =IF(I9<5,1,0) -> 1 | K9: =LOWER(TRIM(C9)) -> alfredo | L9: =LOWER(TRIM(E9)) -> moreno | M9: =IFERROR(IF(J9=1,_xlfn.CONCAT(L9,", ",K9)),0) -> 0 | N9: moreno, alfredo | O9: =B9 -> 8
A10: ALONDRA CARRILLO VIDAL | B10: 9 | C10: ALONDRA | D10: CARRILLO | E10: CARRILLO | F10: VIDAL | I10: =COUNTA(C10:H10) -> 4 | J10: =IF(I10<5,1,0) -> 1 | K10: =LOWER(TRIM(C10)) -> alondra | L10: =LOWER(TRIM(E10)) -> carrillo | M10: =IFERROR(IF(J10=1,_xlfn.CONCAT(L10,", ",K10)),0) -> 0 | N10: carrillo, alondra | O10: =B10 -> 9
A11: ÁLVARO ARTURO JOFRE CÁCERES | B11: 10 | C11: {=_xlfn.TEXTSPLIT(A11," ")} -> #NAME? | D11: #NAME? | E11: #NAME? | F11: #NAME? | I11: =COUNTA(C11:H11) -> 4 | J11: =IF(I11<5,1,0) -> 1 | K11: =LOWER(TRIM(C11)) -> #NAME? | L11: =LOWER(TRIM(E11)) -> #NAME? | M11: =IFERROR(IF(J11=1,_xlfn.CONCAT(L11,", ",K11)),0) -> 0 | N11: jofre, alvaro | O11: =B11 -> 10
A12: ALVIN ANTONIO SALDAÑA MUÑOZ | B12: 11 | C12: {=_xlfn.TEXTSPLIT(A12," ")} -> #NAME? | D12: #NAME? | E12: #NAME? | F12: #NAME? | I12: =COUNTA(C12:H12) -> 4 | J12: =IF(I12<5,1,0) -> 1 | K12: =LOWER(TRIM(C12)) -> #NAME? | L12: =LOWER(TRIM(E12)) -> #NAME? | M12: =IFERROR(IF(J12=1,_xlfn.CONCAT(L12,", ",K12)),0) -> 0 | N12: saldana, alvin | O12: =B12 -> 11
A13: AMAYA PAULINA ÁLVEZ MARIN | B13: 12 | C13: {=_xlfn.TEXTSPLIT(A13," ")} -> #NAME? | D13: #NAME? | E13: #NAME? | F13: #NAME? | I13: =COUNTA(C13:H13) -> 4 | J13: =IF(I13<5,1,0) -> 1 | K13: =LOWER(TRIM(C13)) -> #NAME? | L13: =LOWER(TRIM(E13)) -> #NAME? | M13: =IFERROR(IF(J13=1,_xlfn.CONCAT(L13,", ",K13)),0) -> 0 | N13: alvez, amaya | O13: =B13 -> 12
A14: ANDRÉS NORBERTO CRUZ CARRASCO | B14: 13 | C14: {=_xlfn.TEXTSPLIT(A14," ")} -> #NAME? | D14: #NAME? | E14: #NAME? | F14: #NAME? | I14: =COUNTA(C14:H14) -> 4 | J14: =IF(I14<5,1,0) -> 1 | K14: =LOWER(TRIM(C14)) -> #NAME? | L14: =LOWER(TRIM(E14)) -> #NAME? | M14: =IFERROR(IF(J14=1,_xlfn.CONCAT(L14,", ",K14)),0) -> 0 | N14: cruz, andres | O14: =B14 -> 13
A15: AURORA GENOVEVA DELGADO VERGARA | B15: 14 | C15: {=_xlfn.TEXTSPLIT(A15," ")} -> #NAME? | D15: #NAME? | E15: #NAME? | F15: #NAME? | I15: =COUNTA(C15:H15) -> 4 | J15: =IF(I15<5,1,0) -> 1 | K15: =LOWER(TRIM(C15)) -> #NAME? | L15: =LOWER(TRIM(E15)) -> #NAME? | M15: =IFERROR(IF(J15=1,_xlfn.CONCAT(L15,", ",K15)),0) -> 0 | N15: delgado, aurora | O15: =B15 -> 14
A16: BÁRBARA ALEJANDRA REBOLLEDO AGUIRRE | B16: 15 | C16: {=_xlfn.TEXTSPLIT(A16," ")} -> #NAME? | D16: #NAME? | E16: #NAME? | F16: #NAME? | I16: =COUNTA(C16:H16) -> 4 | J16: =IF(I16<5,1,0) -> 1 | K16: =LOWER(TRIM(C16)) -> #NAME? | L16: =LOWER(TRIM(E16)) -> #NAME? | M16: =IFERROR(IF(J16=1,_xlfn.CONCAT(L16,", ",K16)),0) -> 0 | N16: rebolledo, barbara | O16: =B16 -> 15
A17: BÁRBARA SEPÚLVEDA HALES | B17: 16 | C17: BÁRBARA | D17: SEPÚLVEDA | E17: SEPÚLVEDA | F17: HALES | I17: =COUNTA(C17:H17) -> 4 | J17: =IF(I17<5,1,0) -> 1 | K17: =LOWER(TRIM(C17)) -> bárbara | L17: =LOWER(TRIM(E17)) -> sepúlveda | M17: =IFERROR(IF(J17=1,_xlfn.CONCAT(L17,", ",K17)),0) -> 0 | N17: sepulveda, barbara | O17: =B17 -> 16
A18: BASTIÁN ESTEBAN LABBÉ SALAZAR | B18: 17 | C18: {=_xlfn.TEXTSPLIT(A18," ")} -> #NAME? | D18: #NAME? | E18: #NAME? | F18: #NAME? | I18: =COUNTA(C18:H18) -> 4 | J18: =IF(I18<5,1,0) -> 1 | K18: =LOWER(TRIM(C18)) -> #NAME? | L18: =LOWER(TRIM(E18)) -> #NAME? | M18: =IFERROR(IF(J18=1,_xlfn.CONCAT(L18,", ",K18)),0) -> 0 | N18: labbe, bastian | O18: =B18 -> 17
A19: BEATRIZ DE JESUS SÁNCHEZ MUÑOZ | B19: 18 | C19: BEATRIZ | D19: DE | E19: SÁNCHEZ | F19: MUÑOZ | I19: =COUNTA(C19:H19) -> 4 | J19: =IF(I19<5,1,0) -> 1 | K19: =LOWER(TRIM(C19)) -> beatriz | L19: =LOWER(TRIM(E19)) -> sánchez | M19: =IFERROR(IF(J19=1,_xlfn.CONCAT(L19,", ",K19)),0) -> 0 | N19: sanchez, beatriz | O19: =B19 -> 18
A20: BENITO JOSE BARANDA FERRAN | B20: 19 | C20: {=_xlfn.TEXTSPLIT(A20," ")} -> #NAME? | D20: #NAME? | E20: #NAME? | F20: #NAME? | I20: =COUNTA(C20:H20) -> 4 | J20: =IF(I20<5,1,0) -> 1 | K20: =LOWER(TRIM(C20)) -> #NAME? | L20: =LOWER(TRIM(E20)) -> #NAME? | M20: =IFERROR(IF(J20=1,_xlfn.CONCAT(L20,", ",K20)),0) -> 0 | N20: baranda, benito | O20: =B20 -> 19
A21: BERNARDO ARTURO DE LA MAZA BAÑADOS | B21: 20 | C21: BERNARDO | D21: ARTURO | E21: DE LA MAZA | F21: BAÑADOS | I21: =COUNTA(C21:G21) -> 4 | J21: =IF(I21<5,1,0) -> 1 | K21: =LOWER(TRIM(C21)) -> bernardo | L21: =LOWER(TRIM(E21)) -> de la maza | M21: =IFERROR(IF(J21=1,_xlfn.CONCAT(L21,", ",K21)),0) -> 0 | N21: de la maza, bernardo | O21: =B21 -> 20
A22: BERNARDO FONTAINE TALAVERA | B22: 21 | C22: BERNARDO | D22: FONTAINE | E22: FONTAINE | F22: TALAVERA | I22: =COUNTA(C22:H22) -> 4 | J22: =IF(I22<5,1,0) -> 1 | K22: =LOWER(TRIM(C22)) -> bernardo | L22: =LOWER(TRIM(E22)) -> fontaine | M22: =IFERROR(IF(J22=1,_xlfn.CONCAT(L22,", ",K22)),0) -> 0 | N22: fontaine, bernardo | O22: =B22 -> 21
A23: BESSY MIREYA DEL ROSARIO GALLARDO PRADO | B23: 22 | C23: BESSY | D23: MIREYA | E23: GALLARDO | F23: PRADO | I23: =COUNTA(C23:H23) -> 4 | J23: =IF(I23<5,1,0) -> 1 | K23: =LOWER(TRIM(C23)) -> bessy | L23: =LOWER(TRIM(E23)) -> gallardo | M23: =IFERROR(IF(J23=1,_xlfn.CONCAT(L23,", ",K23)),0) -> 0 | N23: gallardo, bessy | O23: =B23 -> 22
A24: CAMILA IGNACIA ZÁRATE ZÁRATE | B24: 23 | C24: {=_xlfn.TEXTSPLIT(A24," ")} -> #NAME? | D24: #NAME? | E24: #NAME? | F24: #NAME? | I24: =COUNTA(C24:H24) -> 4 | J24: =IF(I24<5,1,0) -> 1 | K24: =LOWER(TRIM(C24)) -> #NAME? | L24: =LOWER(TRIM(E24)) -> #NAME? | M24: =IFERROR(IF(J24=1,_xlfn.CONCAT(L24,", ",K24)),0) -> 0 | N24: zarate, camila | O24: =B24 -> 23
A25: CARLOS MANUEL CALVO MUÑOZ | B25: 24 | C25: {=_xlfn.TEXTSPLIT(A25," ")} -> #NAME? | D25: #NAME? | E25: #NAME? | F25: #NAME? | I25: =COUNTA(C25:H25) -> 4 | J25: =IF(I25<5,1,0) -> 1 | K25: =LOWER(TRIM(C25)) -> #NAME? | L25: =LOWER(TRIM(E25)) -> #NAME? | M25: =IFERROR(IF(J25=1,_xlfn.CONCAT(L25,", ",K25)),0) -> 0 | N25: calvo, carlos | O25: =B25 -> 24
A26: CARLOS MARTÍN ARRAU GARCÍA-HUIDOBRO | B26: 25 | C26: MARTÍN | D26: MARTÍN | E26: ARRAU | F26: GARCÍA-HUIDOBRO | I26: =COUNTA(C26:H26) -> 4 | J26: =IF(I26<5,1,0) -> 1 | K26: =LOWER(TRIM(C26)) -> martín | L26: =LOWER(TRIM(E26)) -> arrau | M26: =IFERROR(IF(J26=1,_xlfn.CONCAT(L26,", ",K26)),0) -> 0 | N26: arrau, martin | O26: =B26 -> 25
A27: CAROL CECILIA BOWN SEPÚLVEDA | B27: 26 | C27: {=_xlfn.TEXTSPLIT(A27," ")} -> #NAME? | D27: #NAME? | E27: #NAME? | F27: #NAME? | I27: =COUNTA(C27:H27) -> 4 | J27: =IF(I27<5,1,0) -> 1 | K27: =LOWER(TRIM(C27)) -> #NAME? | L27: =LOWER(TRIM(E27)) -> #NAME? | M27: =IFERROR(IF(J27=1,_xlfn.CONCAT(L27,", ",K27)),0) -> 0 | N27: bown, carol | O27: =B27 -> 26
A28: CAROLINA ANDREA SEPÚLVEDA SEPÚLVEDA | B28: 27 | C28: {=_xlfn.TEXTSPLIT(A28," ")} -> #NAME? | D28: #NAME? | E28: #NAME? | F28: #NAME? | I28: =COUNTA(C28:H28) -> 4 | J28: =IF(I28<5,1,0) -> 1 | K28: =LOWER(TRIM(C28)) -> #NAME? | L28: =LOWER(TRIM(E28)) -> #NAME? | M28: =IFERROR(IF(J28=1,_xlfn.CONCAT(L28,", ",K28)),0) -> 0 | N28: sepulveda, carolina | O28: =B28 -> 27
A29: CAROLINA CYNTIA VILCHES FUENZALIDA | B29: 28 | C29: {=_xlfn.TEXTSPLIT(A29," ")} -> #NAME? | D29: #NAME? | E29: #NAME? | F29: #NAME? | I29: =COUNTA(C29:H29) -> 4 | J29: =IF(I29<5,1,0) -> 1 | K29: =LOWER(TRIM(C29)) -> #NAME? | L29: =LOWER(TRIM(E29)) -> #NAME? | M29: =IFERROR(IF(J29=1,_xlfn.CONCAT(L29,", ",K29)),0) -> 0 | N29: vilches, carolina | O29: =B29 -> 28
A30: CAROLINA ELIANA VIDELA OSORIO | B30: 29 | C30: {=_xlfn.TEXTSPLIT(A30," ")} -> #NAME? | D30: #NAME? | E30: #NAME? | F30: #NAME? | I30: =COUNTA(C30:H30) -> 4 | J30: =IF(I30<5,1,0) -> 1 | K30: =LOWER(TRIM(C30)) -> #NAME? | L30: =LOWER(TRIM(E30)) -> #NAME? | M30: =IFERROR(IF(J30=1,_xlfn.CONCAT(L30,", ",K30)),0) -> 0 | N30: videla, carolina | O30: =B30 -> 29
A31: CÉSAR IGNACIO VALENZUELA MAASS | B31: 30 | C31: {=_xlfn.TEXTSPLIT(A31," ")} -> #NAME? | D31: #NAME? | E31: #NAME? | F31: #NAME? | I31: =COUNTA(C31:H31) -> 4 | J31: =IF(I31<5,1,0) -> 1 | K31: =LOWER(TRIM(C31)) -> #NAME? | L31: =LOWER(TRIM(E31)) -> #NAME? | M31: =IFERROR(IF(J31=1,_xlfn.CONCAT(L31,", ",K31)),0) -> 0 | N31: valenzuela, cesar | O31: =B31 -> 30
A32: CÉSAR RODRIGO URIBE ARAYA | B32: 31 | C32: {=_xlfn.TEXTSPLIT(A32," ")} -> #NAME? | D32: #NAME? | E32: #NAME? | F32: #NAME? | I32: =COUNTA(C32:H32) -> 4 | J32: =IF(I32<5,1,0) -> 1 | K32: =LOWER(TRIM(C32)) -> #NAME? | L32: =LOWER(TRIM(E32)) -> #NAME? | M32: =IFERROR(IF(J32=1,_xlfn.CONCAT(L32,", ",K32)),0) -> 0 | N32: uribe, cesar | O32: =B32 -> 31
A33: CHRISTIAN PABLO VIERA ALVAREZ | B33: 32 | C33: {=_xlfn.TEXTSPLIT(A33," ")} -> #NAME? | D33: #NAME? | E33: #NAME? | F33: #NAME? | I33: =COUNTA(C33:H33) -> 4 | J33: =IF(I33<5,1,0) -> 1 | K33: =LOWER(TRIM(C33)) -> #NAME? | L33: =LOWER(TRIM(E33)) -> #NAME? | M33: =IFERROR(IF(J33=1,_xlfn.CONCAT(L33,", ",K33)),0) -> 0 | N33: viera, christian | O33: =B33 -> 32
A34: CLAUDIA MABEL CASTRO GUTIÉRREZ | B34: 33 | C34: {=_xlfn.TEXTSPLIT(A34," ")} -> #NAME? | D34: #NAME? | E34: #NAME? | F34: #NAME? | I34: =COUNTA(C34:H34) -> 4 | J34: =IF(I34<5,1,0) -> 1 | K34: =LOWER(TRIM(C34)) -> #NAME? | L34: =LOWER(TRIM(E34)) -> #NAME? | M34: =IFERROR(IF(J34=1,_xlfn.CONCAT(L34,", ",K34)),0) -> 0 | N34: castro, claudia | O34: =B34 -> 33
A35: CLAUDIA MARGARITA LETELIER CORTÉS | B35: 34 | C35: MARGARITA | D35: MARGARITA | E35: LETELIER | F35: CORTÉS | I35: =COUNTA(C35:H35) -> 4 | J35: =IF(I35<5,1,0) -> 1 | K35: =LOWER(TRIM(C35)) -> margarita | L35: =LOWER(TRIM(E35)) -> letelier | M35: =IFERROR(IF(J35=1,_xlfn.CONCAT(L35,", ",K35)),0) -> 0 | N35: letelier, margarita | O35: =B35 -> 34
A36: CLAUDIO FRANCISCO GÓMEZ CASTRO | B36: 35 | C36: {=_xlfn.TEXTSPLIT(A36," ")} -> #NAME? | D36: #NAME? | E36: #NAME? | F36: #NAME? | I36: =COUNTA(C36:H36) -> 4 | J36: =IF(I36<5,1,0) -> 1 | K36: =LOWER(TRIM(C36)) -> #NAME? | L36: =LOWER(TRIM(E36)) -> #NAME? | M36: =IFERROR(IF(J36=1,_xlfn.CONCAT(L36,", ",K36)),0) -> 0 | N36: gomez, claudio | O36: =B36 -> 35
A37: CONSTANZA ANDREA SAN JUAN STANDEN | B37: 36 | C37: CONSTANZA | D37: ANDREA | E37: SAN JUAN | F37: STANDEN | I37: =COUNTA(C37:H37) -> 4 | J37: =IF(I37<5,1,0) -> 1 | K37: =LOWER(TRIM(C37)) -> constanza | L37: =LOWER(TRIM(E37)) -> san juan | M37: =IFERROR(IF(J37=1,_xlfn.CONCAT(L37,", ",K37)),0) -> 0 | N37: san juan, constanza | O37: =B37 -> 36
A38: CONSTANZA GABRIELA SCHONHAUT SOTO | B38: 37 | C38: {=_xlfn.TEXTSPLIT(A38," ")} -> #NAME? | D38: #NAME? | E38: #NAME? | F38: #NAME? | I38: =COUNTA(C38:H38) -> 4 | J38: =IF(I38<5,1,0) -> 1 | K38: =LOWER(TRIM(C38)) -> #NAME? | L38: =LOWER(TRIM(E38)) -> #NAME? | M38: =IFERROR(IF(J38=1,_xlfn.CONCAT(L38,", ",K38)),0) -> 0 | N38: schonhaut, constanza | O38: =B38 -> 37
A39: CONSTANZA VERÓNICA HUBE PORTUS | B39: 38 | C39: {=_xlfn.TEXTSPLIT(A39," ")} -> #NAME? | D39: #NAME? | E39: #NAME? | F39: #NAME? | I39: =COUNTA(C39:H39) -> 4 | J39: =IF(I39<5,1,0) -> 1 | K39: =LOWER(TRIM(C39)) -> #NAME? | L39: =LOWER(TRIM(E39)) -> #NAME? | M39: =IFERROR(IF(J39=1,_xlfn.CONCAT(L39,", ",K39)),0) -> 0 | N39: hube, constanza | O39: =B39 -> 38
A40: CRISTIÁN MONCKEBERG BRUNER | B40: 39 | C40: CRISTIÁN | D40: MONCKEBERG | E40: MONCKEBERG | F40: BRUNER | I40: =COUNTA(C40:H40) -> 4 | J40: =IF(I40<5,1,0) -> 1 | K40: =LOWER(TRIM(C40)) -> cristián | L40: =LOWER(TRIM(E40)) -> monckeberg | M40: =IFERROR(IF(J40=1,_xlfn.CONCAT(L40,", ",K40)),0) -> 0 | N40: monckeberg, cristian | O40: =B40 -> 39
...

Sheet inp_ip_mp
A1: nombre | B1: id | C1: inp_ip_mp
A2: ampuero, adriana | B2: 2 | C2: 0
A3: flores, alejandra | B3: 5 | C3: 0
A4: perez, alejandra | B4: 6 | C4: 0
A5: caiguan, alexis | B5: 7 | C5: 0
